Workbook

Sheet 报关单
A1: 中华人民共和国海关出口货物报关单
A2: 预录入编号： | F2: 申报口岸: | I2: 海关编号:
A3: 境内发货人 | C3: {companyname} | E3: 出境关别 | F3: ( ) | G3: 出口日期 | K3: 申报日期 | O3: 备案号 | U3: 签约地点： | V3: 深圳
A4: {code} | E4: {exitcustoms} | U4: 成交方式: | V4: =I12 -> 0 | W4: SHENZHEN | X4: 付款条件： | Y4: 电汇
A5: 境外收货人 | E5: 运输方式 | F5: ( ) | G5: 运输工具名称及航次号 | K5: 提运单号 | U5: 卖方公司： | V5: {code}
A6: Amazon | E6: 海路 | U6: 卖方地址：
A7: 生产销售单位 | C7: {companyname} | E7: 监管方式 | F7: 9810 | G7: 征免性质 | H7: ( ) | K7: 许可证号 | U7: 卖方电话： | X7: 卖方传真：
A8: {code} | E8: 跨境电商出口海外仓 | G8: 一般征税 | K8: {portnumber} | U8: 买方公司： | V8: LEXIBOOK AMERICA INC.
A9: 合同协议号 | E9: 贸易国(地区) | F9: ( ) | G9: 运抵国(地区) | H9: ( ) | K9: 指运港 | L9: ( ) | O9: 离境口岸 | P9: ( ) | U9: 买方地址：
A10: {number} | E10: {country} | G10: {country} | K10: {country} | U10: 买方电话： | X10: 买方传真：
A11: 包装种类 | E11: 件数 | F11: 毛重（千克） | G11: 净重（千克） | I11: 成交方式 | J11: ( FOB ) | K11: 运费 | N11: 保费 | Q11: 杂费 | U11: 报关简称： | X11: 报关全称：
A12: ( 纸箱 ) | E12: {totalbox} | F12: {totalboxweight} | G12: {totalweight} | T12: 境外收货人： | W12: 境外收货人通常指签订并执行出口贸易合同中的买方或合同指定的收货人，名称一般填报英文名称，检验检疫要求填报其他外文名称的，在英文名称后填报，以半角括号分隔。
A13: 随附单证及编号 | T13: 境外收货人代码： | W13: 非互认国家（地区）AEO企业等其他情形，编码免于填报。对于AEO互认国家（地区）企业的，编码填报AEO编码，填报样式按照海关总署发布的相关公告要求填报（如新加坡AEO企业填报样式为：SG123456789012，韩国AEO企业填报样式为KR1234567，具体见相关公告要求）。
A14: 境外收货人完整显示： | D14: =A6 -> Amazon | T14: 检验检疫附加编号： | W14: 通过以下网站输入10位HS编号，再根据申报要素细分确定3位检疫附加编号
A15: 标记唛码及备注： | C15: 柜号： | T15: 检疫局网址-编码查询： | W15: https://e-service.shciq.gov.cn/shesp/
A16: 备注： | B16: N/M | T16: 查申报要素网址： | W16: http://www.hscode.net/IntegrateQueries/QueryYS/
T17: 合计： | W17: 贸易国：出口是指合同买方所在的国家（地区），需填写准确，以后可能会影响收汇。
A18: 特殊关系确认: | D18: 价格影响确认： | F18: 支付特许权使用费: | I18: 自报自缴: | K18: 出口不填 | L18: 原产国/目的国/货源地未注明的项默认与提供的项相同 | T18: {totalweight} | U18: {totalboxweight} | V18: {totalbox}
A19: 项号 | B19: 商品编号 | D19: 商品名称及规格型号 | G19: 数量及单位 | I19: 单价/总价/币制 | K19: 原产国（地区） | M19: 最终目的国（地区） | P19: 境内货源地 | S19: 征免 | T19: 净重 | U19: 毛重 | V19: 件数
A20: {list.index} | B20: {list.model} | D20: {list.materialcn} | G20: {list.weight} | H20: {list.weightunit} | I20: {list.itemprice} | K20: 中国 | M20: {country} | P20: 深圳特区 | S20: 照章征税 | T20: {list.weight} | U20: {totalboxweight} | V20: {totalbox}
D21: {list.name} | G21: {list.qty2} | H21: {list.unit2} | I21: {list.price}
G22: {list.qty} | H22: {list.unit} | I22: {list.currency}

Sheet 发票
A1: 發票 INVOICE
F2: 編 號 NO: | G2: =报关单!A10 -> {number}
A3: 商 號 Sold to Massrs: | C3: =报关单!A6 -> Amazon | F3: 日 期 DATE: | G3: =TODAY()-1 -> 46163
F6: 成交方式： | G6: =报关单!V4 -> 0 | H6: =报关单!W4 -> SHENZHEN
A7: 標記號碼 Mark & No | C7: 貨物名稱 Description | D7: 數量 Quantity | F7: 單價 Unit price | G7: 總金額 Amount
A8: N/M | C8: =OFFSET(报关单!$D$1,ROW(报关单!D1)*3+16,0) -> {list.materialcn} | D8: =OFFSET(报关单!$G$1,ROW(报关单!G1)*3+18,0) -> {list.qty} | E8: =OFFSET(报关单!$H$1,ROW(报关单!H1)*3+18,0) -> {list.unit} | F8: =IFERROR(H8/D8,0) -> 0 | G8: =OFFSET(报关单!$I$1,ROW(报关单!I1)*3+18,0) -> {list.currency} | H8: =OFFSET(报关单!$I$1,ROW(报关单!I1)*3+17,0) -> {list.price}
C9: =OFFSET(报关单!$D$1,ROW(报关单!D2)*3+16,0) -> 0 | D9: =OFFSET(报关单!$G$1,ROW(报关单!G2)*3+18,0) -> 0 | E9: =OFFSET(报关单!$H$1,ROW(报关单!H2)*3+18,0) -> 0 | F9: =IFERROR(H9/D9,0) -> 0 | G9: =OFFSET(报关单!$I$1,ROW(报关单!I2)*3+18,0) -> 0 | H9: =OFFSET(报关单!$I$1,ROW(报关单!I2)*3+17,0) -> 0
C10: =OFFSET(报关单!$D$1,ROW(报关单!D3)*3+16,0) -> 0 | D10: =OFFSET(报关单!$G$1,ROW(报关单!G3)*3+18,0) -> 0 | E10: =OFFSET(报关单!$H$1,ROW(报关单!H3)*3+18,0) -> 0 | F10: =IFERROR(H10/D10,0) -> 0 | G10: =OFFSET(报关单!$I$1,ROW(报关单!I3)*3+18,0) -> 0 | H10: =OFFSET(报关单!$I$1,ROW(报关单!I3)*3+17,0) -> 0
C11: =OFFSET(报关单!$D$1,ROW(报关单!D4)*3+16,0) -> 0 | D11: =OFFSET(报关单!$G$1,ROW(报关单!G4)*3+18,0) -> 0 | E11: =OFFSET(报关单!$H$1,ROW(报关单!H4)*3+18,0) -> 0 | F11: =IFERROR(H11/D11,0) -> 0 | G11: =OFFSET(报关单!$I$1,ROW(报关单!I4)*3+18,0) -> 0 | H11: =OFFSET(报关单!$I$1,ROW(报关单!I4)*3+17,0) -> 0
C12: =OFFSET(报关单!$D$1,ROW(报关单!D5)*3+16,0) -> 0 | D12: =OFFSET(报关单!$G$1,ROW(报关单!G5)*3+18,0) -> 0 | E12: =OFFSET(报关单!$H$1,ROW(报关单!H5)*3+18,0) -> 0 | F12: =IFERROR(H12/D12,0) -> 0 | G12: =OFFSET(报关单!$I$1,ROW(报关单!I5)*3+18,0) -> 0 | H12: =OFFSET(报关单!$I$1,ROW(报关单!I5)*3+17,0) -> 0
C13: =OFFSET(报关单!$D$1,ROW(报关单!D6)*3+16,0) -> 0 | D13: =OFFSET(报关单!$G$1,ROW(报关单!G6)*3+18,0) -> 0 | E13: =OFFSET(报关单!$H$1,ROW(报关单!H6)*3+18,0) -> 0 | F13: =IFERROR(H13/D13,0) -> 0 | G13: =OFFSET(报关单!$I$1,ROW(报关单!I6)*3+18,0) -> 0 | H13: =OFFSET(报关单!$I$1,ROW(报关单!I6)*3+17,0) -> 0
C14: =OFFSET(报关单!$D$1,ROW(报关单!D7)*3+16,0) -> 0 | D14: =OFFSET(报关单!$G$1,ROW(报关单!G7)*3+18,0) -> 0 | E14: =OFFSET(报关单!$H$1,ROW(报关单!H7)*3+18,0) -> 0 | F14: =IFERROR(H14/D14,0) -> 0 | G14: =OFFSET(报关单!$I$1,ROW(报关单!I7)*3+18,0) -> 0 | H14: =OFFSET(报关单!$I$1,ROW(报关单!I7)*3+17,0) -> 0
C15: =OFFSET(报关单!$D$1,ROW(报关单!D8)*3+16,0) -> 0 | D15: =OFFSET(报关单!$G$1,ROW(报关单!G8)*3+18,0) -> 0 | E15: =OFFSET(报关单!$H$1,ROW(报关单!H8)*3+18,0) -> 0 | F15: =IFERROR(H15/D15,0) -> 0 | G15: =OFFSET(报关单!$I$1,ROW(报关单!I8)*3+18,0) -> 0 | H15: =OFFSET(报关单!$I$1,ROW(报关单!I8)*3+17,0) -> 0
C16: =OFFSET(报关单!$D$1,ROW(报关单!D9)*3+16,0) -> 0 | D16: =OFFSET(报关单!$G$1,ROW(报关单!G9)*3+18,0) -> 0 | E16: =OFFSET(报关单!$H$1,ROW(报关单!H9)*3+18,0) -> 0 | F16: =IFERROR(H16/D16,0) -> 0 | G16: =OFFSET(报关单!$I$1,ROW(报关单!I9)*3+18,0) -> 0 | H16: =OFFSET(报关单!$I$1,ROW(报关单!I9)*3+17,0) -> 0
C17: =OFFSET(报关单!$D$1,ROW(报关单!D10)*3+16,0) -> 0 | D17: =OFFSET(报关单!$G$1,ROW(报关单!G10)*3+18,0) -> 0 | E17: =OFFSET(报关单!$H$1,ROW(报关单!H10)*3+18,0) -> 0 | F17: =IFERROR(H17/D17,0) -> 0 | G17: =OFFSET(报关单!$I$1,ROW(报关单!I10)*3+18,0) -> 0 | H17: =OFFSET(报关单!$I$1,ROW(报关单!I10)*3+17,0) -> 0
C18: =OFFSET(报关单!$D$1,ROW(报关单!D11)*3+16,0) -> 0 | D18: =OFFSET(报关单!$G$1,ROW(报关单!G11)*3+18,0) -> 0 | E18: =OFFSET(报关单!$H$1,ROW(报关单!H11)*3+18,0) -> 0 | F18: =IFERROR(H18/D18,0) -> 0 | G18: =OFFSET(报关单!$I$1,ROW(报关单!I11)*3+18,0) -> 0 | H18: =OFFSET(报关单!$I$1,ROW(报关单!I11)*3+17,0) -> 0
C19: =OFFSET(报关单!$D$1,ROW(报关单!D12)*3+16,0) -> 0 | D19: =OFFSET(报关单!$G$1,ROW(报关单!G12)*3+18,0) -> 0 | E19: =OFFSET(报关单!$H$1,ROW(报关单!H12)*3+18,0) -> 0 | F19: =IFERROR(H19/D19,0) -> 0 | G19: =OFFSET(报关单!$I$1,ROW(报关单!I12)*3+18,0) -> 0 | H19: =OFFSET(报关单!$I$1,ROW(报关单!I12)*3+17,0) -> 0
C20: =OFFSET(报关单!$D$1,ROW(报关单!D13)*3+16,0) -> 0 | D20: =OFFSET(报关单!$G$1,ROW(报关单!G13)*3+18,0) -> 0 | E20: =OFFSET(报关单!$H$1,ROW(报关单!H13)*3+18,0) -> 0 | F20: =IFERROR(H20/D20,0) -> 0 | G20: =OFFSET(报关单!$I$1,ROW(报关单!I13)*3+18,0) -> 0 | H20: =OFFSET(报关单!$I$1,ROW(报关单!I13)*3+17,0) -> 0
... C59: =OFFSET(报关单!$D$1,ROW(报关单!D52)*3+16,0) -> 0 | D59: =OFFSET(报关单!$G$1,ROW(报关单!G52)*3+18,0) -> 0 | E59: =OFFSET(报关单!$H$1,ROW(报关单!H52)*3+18,0) -> 0 | F59: =IFERROR(H59/D59,0) -> 0 | G59: =OFFSET(报关单!$I$1,ROW(报关单!I52)*3+18,0) -> 0 | H59: =OFFSET(报关单!$I$1,ROW(报关单!I52)*3+17,0) -> 0
A60: =IF(G60="CNY","总计人民币:",IF(G60="USD","总计美元: "," ")) | C60: =H60 -> 0 | F60: TOTAL: | G60: =OFFSET(报关单!$I$1,ROW(报关单!I76)*3+18,0) -> 0 | H60: =SUM(H8:J59) -> 0
A61: 唛头 Marks | F61: 备注：
C67: .

Sheet 箱单
B2: 装 箱 单 PACKING LIST
F3: 日期 Date： | G3: =TODAY()-1 -> 46163
F4: 发票编号 Invoice No: | G4: =发票!G2 -> {number}
A5: 客户 To Messrs: | B5: =发票!C3 -> Amazon | F5: 合同号 Contract No: | G5: =发票!G2 -> {number}
A7: 船名 Shipped by： | C7: 由 深圳 至 | D7: =报关单!M20 -> {country} | F7: 付款条件 Terms of Payment: | G7: =报关单!Y4 -> 电汇
A9: 箱号 Ctn.No. | B9: 货物名称及规格 Description | C9: 箱数： Pkg： | D9: 数量： Ge.Quantity | F9: 毛重(KG)： G.W.(KG): | G9: 净重(KG)： N.W.(KG):
A10: =发票!A8 -> N/M | B10: =发票!C8 -> {list.materialcn} | C10: =报关单!V18 -> {totalbox} | D10: =发票!D8 -> {list.qty} | E10: =发票!E8 -> {list.unit} | F10: =报关单!U18 -> {totalboxweight} | G10: =报关单!T20 -> {list.weight}
B11: =发票!C9 -> 0 | D11: =发票!D9 -> 0 | E11: =发票!E9 -> 0 | G11: =OFFSET(报关单!$T$1,ROW(报关单!T2)*3+16,0) -> 0
B12: =发票!C10 -> 0 | D12: =发票!D10 -> 0 | E12: =发票!E10 -> 0 | G12: =OFFSET(报关单!$T$1,ROW(报关单!T3)*3+16,0) -> 0
B13: =发票!C11 -> 0 | D13: =发票!D11 -> 0 | E13: =发票!E11 -> 0 | G13: =OFFSET(报关单!$T$1,ROW(报关单!T4)*3+16,0) -> 0
B14: =发票!C12 -> 0 | D14: =发票!D12 -> 0 | E14: =发票!E12 -> 0 | G14: =OFFSET(报关单!$T$1,ROW(报关单!T5)*3+16,0) -> 0
B15: =发票!C13 -> 0 | D15: =发票!D13 -> 0 | E15: =发票!E13 -> 0 | G15: =OFFSET(报关单!$T$1,ROW(报关单!T6)*3+16,0) -> 0
B16: =发票!C14 -> 0 | D16: =发票!D14 -> 0 | E16: =发票!E14 -> 0 | G16: =OFFSET(报关单!$T$1,ROW(报关单!T7)*3+16,0) -> 0
B17: =发票!C15 -> 0 | D17: =发票!D15 -> 0 | E17: =发票!E15 -> 0 | G17: =OFFSET(报关单!$T$1,ROW(报关单!T8)*3+16,0) -> 0
B18: =发票!C16 -> 0 | D18: =发票!D16 -> 0 | E18: =发票!E16 -> 0 | G18: =OFFSET(报关单!$T$1,ROW(报关单!T9)*3+16,0) -> 0
B19: =发票!C17 -> 0 | D19: =发票!D17 -> 0 | E19: =发票!E17 -> 0 | G19: =OFFSET(报关单!$T$1,ROW(报关单!T10)*3+16,0) -> 0
B20: =发票!C18 -> 0 | D20: =发票!D18 -> 0 | E20: =发票!E18 -> 0 | G20: =OFFSET(报关单!$T$1,ROW(报关单!T11)*3+16,0) -> 0
B21: =发票!C19 -> 0 | D21: =发票!D19 -> 0 | E21: =发票!E19 -> 0 | G21: =OFFSET(报关单!$T$1,ROW(报关单!T12)*3+16,0) -> 0
B22: =发票!C20 -> 0 | D22: =发票!D20 -> 0 | E22: =发票!E20 -> 0 | G22: =OFFSET(报关单!$T$1,ROW(报关单!T13)*3+16,0) -> 0
... B46: =发票!C44 -> 0 | D46: =发票!D44 -> 0 | E46: =发票!E44 -> 0 | G46: =OFFSET(报关单!$T$1,ROW(报关单!T37)*3+16,0) -> 0
B47: =发票!C46 -> 0 | D47: =发票!D46 -> 0 | E47: =发票!E46 -> 0 | G47: =报关单!T58 -> 0
B48: =发票!C47 -> 0 | D48: =发票!D47 -> 0 | E48: =发票!E47 -> 0 | G48: =OFFSET(报关单!$T$1,ROW(报关单!T40)*3+16,0) -> 0
B49: =发票!C48 -> 0 | D49: =发票!D48 -> 0 | E49: =发票!E48 -> 0 | G49: =OFFSET(报关单!$T$1,ROW(报关单!T41)*3+16,0) -> 0
B50: =发票!C49 -> 0 | D50: =发票!D49 -> 0 | E50: =发票!E49 -> 0 | G50: =OFFSET(报关单!$T$1,ROW(报关单!T42)*3+16,0) -> 0
B51: =发票!C50 -> 0 | D51: =发票!D50 -> 0 | E51: =发票!E50 -> 0 | G51: =OFFSET(报关单!$T$1,ROW(报关单!T43)*3+16,0) -> 0
B52: =发票!C51 -> 0 | D52: =发票!D51 -> 0 | E52: =发票!E51 -> 0 | G52: =OFFSET(报关单!$T$1,ROW(报关单!T44)*3+16,0) -> 0
B53: =发票!C52 -> 0 | D53: =发票!D52 -> 0 | E53: =发票!E52 -> 0 | G53: =OFFSET(报关单!$T$1,ROW(报关单!T45)*3+16,0) -> 0
B54: =发票!C53 -> 0 | D54: =发票!D53 -> 0 | E54: =发票!E53 -> 0 | G54: =OFFSET(报关单!$T$1,ROW(报关单!T46)*3+16,0) -> 0
B55: =发票!C54 -> 0 | D55: =发票!D54 -> 0 | E55: =发票!E54 -> 0 | G55: =OFFSET(报关单!$T$1,ROW(报关单!T47)*3+16,0) -> 0
B56: =发票!C55 -> 0 | D56: =发票!D55 -> 0 | E56: =发票!E55 -> 0 | G56: =OFFSET(报关单!$T$1,ROW(报关单!T48)*3+16,0) -> 0
B57: =发票!C56 -> 0 | D57: =发票!D56 -> 0 | E57: =发票!E56 -> 0 | G57: =OFFSET(报关单!$T$1,ROW(报关单!T49)*3+16,0) -> 0
B58: =发票!C57 -> 0 | D58: =发票!D57 -> 0 | E58: =发票!E57 -> 0 | G58: =OFFSET(报关单!$T$1,ROW(报关单!T50)*3+16,0) -> 0
B59: =发票!C58 -> 0 | D59: =发票!D58 -> 0 | E59: =发票!E58 -> 0 | G59: =OFFSET(报关单!$T$1,ROW(报关单!T51)*3+16,0) -> 0
B60: =发票!C59 -> 0 | D60: =发票!D59 -> 0 | E60: =发票!E59 -> 0 | G60: =OFFSET(报关单!$T$1,ROW(报关单!T52)*3+16,0) -> 0
A61: 合计 Total | B61: =SUM(B10:B60) -> 0 | C61: =SUM(C10:C60) -> 0 | D61: =SUM(D10:D60) -> 0 | E61: =SUM(E10:E60) -> 0 | F61: =SUM(F10:F60) -> 0 | G61: =SUM(G10:G60) -> 0
A62: 唛头 Marks

Sheet 合同
B1: 合 同 SALES CONTRACT
B2: 卖 方： | C2: =报关单!V5 -> {code}
B3: Sellers:
B4: 地 址：
B5: Address: | F5: 合同号码
B6: 电 话： | C6: =报关单!V7 -> 0 | D6: 传 真 | E6: =报关单!Y7 -> 0 | F6: Contract No: | G6: =报关单!A10 -> {number}
B7: TEL: | D7: FAX: | F7: 日 期
B8: 买 方： | C8: =报关单!A6 -> Amazon | F8: Date: | G8: =TODAY()-25 -> 46139
B9: Buyers： | F9: 签约地点
B10: 地 址： | C10: =报关单!V9 -> 0 | F10: Signed at: | G10: =报关单!V3 -> 深圳
B11: Address: | F11: 成交方式： Trade Term: | G11: =报关单!V4 -> 0 | H11: =报关单!W4 -> SHENZHEN
B12: 电 话 | C12: =报关单!V10 -> 0 | D12: 传 真 | E12: =报关单!Y10 -> 0
B13: TEL: | D13: FAX:
B14: 经买卖双方确认根据下列条款订立本合同
B15: This contract is made out by the Sellers and Buyers as per the following terms and conditions mutuilly confirmed:
B16: (1)货物名称 | D16: (2) 数 量 | E16: (3)单 位 | F16: (4)单价 | G16: (5) 金 额
B17: Name of commodity | D17: Quantity | E17: Unit | F17: Unit Price | G17: Amount
B18: =发票!C8 -> {list.materialcn} | D18: =发票!D8 -> {list.qty} | E18: =发票!E8 -> {list.unit} | F18: =发票!F8 -> 0 | G18: =发票!G8 -> {list.currency} | H18: =发票!H8 -> {list.price}
B19: =发票!C9 -> 0 | D19: =发票!D9 -> 0 | E19: =发票!E9 -> 0 | F19: =发票!F9 -> 0 | G19: =发票!G9 -> 0 | H19: =发票!H9 -> 0
B20: =发票!C10 -> 0 | D20: =发票!D10 -> 0 | E20: =发票!E10 -> 0 | F20: =发票!F10 -> 0 | G20: =发票!G10 -> 0 | H20: =发票!H10 -> 0
B21: =发票!C11 -> 0 | D21: =发票!D11 -> 0 | E21: =发票!E11 -> 0 | F21: =发票!F11 -> 0 | G21: =发票!G11 -> 0 | H21: =发票!H11 -> 0
B22: =发票!C12 -> 0 | D22: =发票!D12 -> 0 | E22: =发票!E12 -> 0 | F22: =发票!F12 -> 0 | G22: =发票!G12 -> 0 | H22: =发票!H12 -> 0
B23: =发票!C13 -> 0 | D23: =发票!D13 -> 0 | E23: =发票!E13 -> 0 | F23: =发票!F13 -> 0 | G23: =发票!G13 -> 0 | H23: =发票!H13 -> 0
B24: =发票!C14 -> 0 | D24: =发票!D14 -> 0 | E24: =发票!E14 -> 0 | F24: =发票!F14 -> 0 | G24: =发票!G14 -> 0 | H24: =发票!H14 -> 0
B25: =发票!C15 -> 0 | D25: =发票!D15 -> 0 | E25: =发票!E15 -> 0 | F25: =发票!F15 -> 0 | G25: =发票!G15 -> 0 | H25: =发票!H15 -> 0
B26: =发票!C16 -> 0 | D26: =发票!D16 -> 0 | E26: =发票!E16 -> 0 | F26: =发票!F16 -> 0 | G26: =发票!G16 -> 0 | H26: =发票!H16 -> 0
B27: =发票!C17 -> 0 | D27: =发票!D17 -> 0 | E27: =发票!E17 -> 0 | F27: =发票!F17 -> 0 | G27: =发票!G17 -> 0 | H27: =发票!H17 -> 0
B28: =发票!C18 -> 0 | D28: =发票!D18 -> 0 | E28: =发票!E18 -> 0 | F28: =发票!F18 -> 0 | G28: =发票!G18 -> 0 | H28: =发票!H18 -> 0
B29: =发票!C19 -> 0 | D29: =发票!D19 -> 0 | E29: =发票!E19 -> 0 | F29: =发票!F19 -> 0 | G29: =发票!G19 -> 0 | H29: =发票!H19 -> 0
... B69: =发票!C59 -> 0 | D69: =发票!D59 -> 0 | E69: =发票!E59 -> 0 | F69: =发票!F59 -> 0 | G69: =发票!G59 -> 0 | H69: =发票!H59 -> 0
B70: 数量及总值允许有 2 %的增减。 | F70: 总 值 | G70: =G18 -> {list.currency} | H70: =SUM(H18:I69) -> 0
B71: 2 % more or less both in amount and quantity allowed. | F71: Total Amount:
B72: (6)合同总值（大写） | D72: =IF(G70="CNY","总计人民币:",IF(G70="USD","总计美元: "," ")) | E72: =H70 -> 0
B73: Total Value in Word: FORTY TWO THOUSAND FOUR HUNDRED AND SEVENTY THREE AND CENTS TWENTY EIGHT ONLY.
B74: (7)包装及唛头
B75: Packing and shipping Marks:
B76: (8)装运期
B77: Time of Shipment: | C77: =TODAY()+15 -> 46179 | E77: 之前
B78: (9)装运口岸和目的地 深圳--- | C78: =报关单!V3 -> 深圳 | D78: =箱单!D7 -> {country} | E78: 准许分批与转船。
B79: Loading Port & Destination:From Shenzhen-- To Hongkong with transhipment and partial ship ments allowed
...
